<?xml version="1.0"?>
<sdf version='1.6'>
  <model name='Door'>

    <link name='hinge'>
      <pose frame=''>0 -0.43 0 0 -0 0</pose>
      <inertial>
        <pose>-0.00057 0 0 0 -0 0</pose>
        <mass>3</mass>
        <inertia>
          <ixx>11.685</ixx>
          <ixy>7.223e-05</ixy>
          <ixz>0.00010293</ixz>
          <iyy>14.036</iyy>
          <iyz>-2.5678e-05</iyz>
          <izz>2.3663</izz>
        </inertia>
      </inertial>
      <velocity_decay>
        <linear>0</linear>
        <angular>0</angular>
      </velocity_decay>
    </link>
    <link name='door'>
      <pose frame=''>0.00057 -0.026006 0 0 -0 1.5708</pose>
      <inertial>
        <pose frame=''>0.00057 -0.026006 0 0 -0 1.5708</pose>
        <mass>33.399</mass>
        <inertia>
          <ixx>11.685</ixx>
          <ixy>7.223e-05</ixy>
          <ixz>0.00010293</ixz>
          <iyy>14.036</iyy>
          <iyz>-2.5678e-05</iyz>
          <izz>2.3663</izz>
        </inertia>
      </inertial>

      <collision name='door_collision'>
        <pose frame=''>0 0 0 1.5708 -0 0</pose>
        <geometry>
          <mesh>
            <scale>1 1 1</scale>
            <uri>model://Door/meshes/Door_in.dae</uri>
          </mesh>
        </geometry>
      </collision>
      <visual name='door_visual'>
        <pose frame=''>0 0 0 1.5708 -0 0</pose>
        <geometry>
          <mesh>
            <scale>1 1 1</scale>
            <uri>model://Door/meshes/Door_in.dae</uri>
          </mesh>
        </geometry>
      </visual>
      <gravity>1</gravity>
      <velocity_decay>
        <linear>0</linear>
        <angular>0</angular>
      </velocity_decay>
      <self_collide>0</self_collide>
    </link>

    <joint name='door_hinge' type='revolute'>
      <parent>hinge</parent>
      <child>door</child>
      <pose frame=''>-0.43 0 0 0 -0 0</pose>
      <axis>
        <xyz>0 0 1</xyz>
        <limit>
          <lower>0</lower>
          <upper>1.57</upper>
          <effort>0</effort>
          <velocity>10</velocity>
        </limit>
        <dynamics/>
      </axis>
    </joint>

    <joint name='floor_link' type='revolute'>
      <child>hinge</child>
      <parent>world</parent>
      <axis>
        <xyz>0 0 1</xyz>
        <limit>
          <lower>0</lower>
          <upper>0</upper>
          <effort>0</effort>
          <velocity>0</velocity>
        </limit>
        <dynamics/>
      </axis>
    </joint>

  <plugin name="door_plugin" filename="libdoor_plugin.so">
    <door_type>flip</door_type>
    <model_domain_space>door_</model_domain_space>
    <door_direction>counter_clockwise</door_direction>
  </plugin>
  
  </model>
</sdf>
